======================================================================
Welcome to the Python Debugging Information Utility ABOUTRABBIT.PY
Date and Time: 2024-05-14 at 10:42 AM
======================================================================
Yay! RabbitMQ is installed.
Pika version 1.3.2 connecting to ('::1', 5672, 0, 0)
Socket failed to connect: <socket.socket fd=9, family=30, type=1, proto=6, laddr=('::1', 61248, 0, 0)>; error=61 (Connection refused)
TCP Connection attempt failed: ConnectionRefusedError(61, 'Connection refused'); dest=(<AddressFamily.AF_INET6: 30>, <SocketKind.SOCK_STREAM: 1>, 6, '', ('::1', 5672, 0, 0))
AMQPConnector - reporting failure: AMQPConnectorSocketConnectError: ConnectionRefusedError(61, 'Connection refused')
Pika version 1.3.2 connecting to ('127.0.0.1', 5672)
Socket failed to connect: <socket.socket fd=9, family=2, type=1, proto=6, laddr=('127.0.0.1', 61249)>; error=61 (Connection refused)
TCP Connection attempt failed: ConnectionRefusedError(61, 'Connection refused'); dest=(<AddressFamily.AF_INET: 2>, <SocketKind.SOCK_STREAM: 1>, 6, '', ('127.0.0.1', 5672))
AMQPConnector - reporting failure: AMQPConnectorSocketConnectError: ConnectionRefusedError(61, 'Connection refused')
AMQP connection workflow failed: AMQPConnectionWorkflowFailed: 2 exceptions in all; last exception - AMQPConnectorSocketConnectError: ConnectionRefusedError(61, 'Connection refused'); first exception - AMQPConnectorSocketConnectError: ConnectionRefusedError(61, 'Connection refused').
AMQPConnectionWorkflow - reporting failure: AMQPConnectionWorkflowFailed: 2 exceptions in all; last exception - AMQPConnectorSocketConnectError: ConnectionRefusedError(61, 'Connection refused'); first exception - AMQPConnectorSocketConnectError: ConnectionRefusedError(61, 'Connection refused')
Connection workflow failed: AMQPConnectionWorkflowFailed: 2 exceptions in all; last exception - AMQPConnectorSocketConnectError: ConnectionRefusedError(61, 'Connection refused'); first exception - AMQPConnectorSocketConnectError: ConnectionRefusedError(61, 'Connection refused')
Error in _create_connection().
Traceback (most recent call last):
  File "/Users/joseguzman/Library/CloudStorage/OneDrive-nwmissouri.edu/Summer1/44671/streaming-03-rabbitmq/.venv/lib/python3.12/site-packages/pika/adapters/blocking_connection.py", line 451, in _create_connection
    raise self._reap_last_connection_workflow_error(error)
pika.exceptions.AMQPConnectionError
RabbitMQ is NOT running. Please start RabbitMQ.
Try the following command: brew services start rabbitmq
======================================================================
